<?xml version="1.0" encoding="utf-8"?>
<!-- This URDF was automatically created by SolidWorks to URDF Exporter! Originally created by Stephen Brawner (brawner@gmail.com) 
     Commit Version: 1.6.0-4-g7f85cfe  Build Version: 1.6.7995.38578
     For more information, please see http://wiki.ros.org/sw_urdf_exporter -->
<robot name="fishbot">

  <!-- Robot Footprint -->
  <link name="base_footprint"/>
  <joint name="base_joint" type="fixed">
    <parent link="base_footprint"/>
    <child link="base_link"/>
    <origin xyz="0.0 0.0 0.066" rpy="0 0 0"/>
  </joint>

  <!-- Base link -->
  <link name="base_link">
    <inertial>
      <origin xyz="5.5511E-17 -4.3368E-18 -0.014001" rpy="0 0 0" />
      <mass value="0.41196" />
      <inertia ixx="0.00020336" ixy="-2.5099E-20" ixz="5.1812E-21" iyy="9.0052E-05" iyz="-1.363E-22" izz="0.00024415" />
    </inertial>
    <visual>
      <origin xyz="0 0 0" rpy="0 0 0" />
      <geometry>
        <mesh filename="package://fishbot_description/meshes/base_link.STL" />
      </geometry>
      <material name="">
        <color rgba="0.89804 0.91765 0.92941 1" />
      </material>
    </visual>
    <collision>
      <origin xyz="0 0 0" rpy="0 0 0" />
      <geometry>
        <mesh filename="package://fishbot_description/meshes/base_link.STL" />
      </geometry>
    </collision>
  </link>

  <link name="leftwheel_link">
    <inertial>
      <origin xyz="2.5134E-09 -0.0039664 -4.6993E-09" rpy="0 0 0" />
      <mass value="0.051111" />
      <inertia ixx="2.2477E-05" ixy="-1.2547E-13" ixz="-2.7101E-13" iyy="3.9119E-05" iyz="2.3458E-13" izz="2.2477E-05" />
    </inertial>
    <visual>
      <origin xyz="0 0 0" rpy="0 0 0" />
      <geometry>
        <mesh filename="package://fishbot_description/meshes/leftwheel_link.STL" />
      </geometry>
      <material name="">
        <color rgba="1 1 1 1" />
      </material>
    </visual>
    <collision>
      <origin xyz="0 0 0" rpy="0 0 0" />
      <geometry>
        <mesh filename="package://fishbot_description/meshes/leftwheel_link.STL" />
      </geometry>
    </collision>
  </link>

  <joint name="leftwheel_joint" type="continuous">
    <origin xyz="0 0.0785 -0.0335" rpy="0 0 0" />
    <parent link="base_link" />
    <child link="leftwheel_link" />
    <axis xyz="0 1 0" />
  </joint>

  <link name="rightwheel_link">
    <inertial>
      <origin xyz="3.7223E-09 0.0039664 -3.8138E-09" rpy="0 0 0" />
      <mass value="0.051111" />
      <inertia ixx="2.2477E-05" ixy="1.8581E-13" ixz="-3.2573E-13" iyy="3.9119E-05" iyz="-1.9038E-13" izz="2.2477E-05" />
    </inertial>
    <visual>
      <origin xyz="0 0 0" rpy="0 0 0" />
      <geometry>
        <mesh filename="package://fishbot_description/meshes/rightwheel_link.STL" />
      </geometry>
      <material name="">
        <color rgba="1 1 1 1" />
      </material>
    </visual>
    <collision>
      <origin xyz="0 0 0" rpy="0 0 0" />
      <geometry>
        <mesh filename="package://fishbot_description/meshes/rightwheel_link.STL" />
      </geometry>
    </collision>
  </link>

  <joint name="rightwheel_joint" type="continuous">
    <origin xyz="0 -0.0785 -0.0335" rpy="0 0 0" />
    <parent link="base_link" />
    <child link="rightwheel_link" />
    <axis xyz="0 -1 0" />
  </joint>

  <link name="camera_link">
    <inertial>
      <origin xyz="-0.011636 -4.7705E-18 0" rpy="0 0 0" />
      <mass value="0.0064397" />
      <inertia ixx="4.5912E-07" ixy="4.8691E-22" ixz="5.5251E-25" iyy="5.6822E-07" iyz="-5.0003E-23" izz="5.7269E-07"/>
    </inertial>
    <visual>
      <origin xyz="0 0 0" rpy="0 0 0"/>
      <geometry>
        <mesh filename="package://fishbot_description/meshes/camera_link.STL"/>
      </geometry>
      <material name="">
        <color rgba="0.79216 0.81961 0.93333 1" />
      </material>
    </visual>
    <collision>
      <origin xyz="0 0 0" rpy="0 0 0" />
      <geometry>
        <mesh filename="package://fishbot_description/meshes/camera_link.STL" />
      </geometry>
    </collision>
  </link>

  <joint name="camera_joint" type="fixed">
    <origin xyz="0.0529 0 0.013" rpy="0 0 0" />
    <parent link="base_link" />
    <child link="camera_link" />
    <axis xyz="0 0 0" />
  </joint>

  <link name="imu_link">
    <inertial>
      <origin xyz="5.5511E-17 4.3368E-17 0.001" rpy="0 0 0" />
      <mass value="0.00044961" />
      <inertia ixx="8.5824E-09" ixy="-5.284E-25" ixz="-1.2622E-26" iyy="8.5824E-09" iyz="-9.8608E-27" izz="1.6876E-08" />
    </inertial>
    <visual>
      <origin xyz="0 0 0" rpy="0 0 0" />
      <geometry>
        <mesh filename="package://fishbot_description/meshes/imu_link.STL" />
      </geometry>
      <material name="">
        <color rgba="1 1 1 1" />
      </material>
    </visual>
    <collision>
      <origin xyz="0 0 0" rpy="0 0 0" />
      <geometry>
        <mesh filename="package://fishbot_description/meshes/imu_link.STL" />
      </geometry>
    </collision>
  </link>

  <joint name="imu_joint" type="fixed">
    <origin xyz="0 0 0.029" rpy="0 0 0" />
    <parent link="base_link" />
    <child link="imu_link" />
    <axis xyz="0 0 0" />
  </joint>

</robot>